[2025-09-06T16:50:59.222+0000] {taskinstance.py:1956} INFO - Dependencies all met for dep_context=non-requeueable deps ti=<TaskInstance: weather_etl_pipeline.send_weather_email manual__2025-09-06T16:50:56.450281+00:00 [queued]>
[2025-09-06T16:50:59.227+0000] {taskinstance.py:1956} INFO - Dependencies all met for dep_context=requeueable deps ti=<TaskInstance: weather_etl_pipeline.send_weather_email manual__2025-09-06T16:50:56.450281+00:00 [queued]>
[2025-09-06T16:50:59.227+0000] {taskinstance.py:2170} INFO - Starting attempt 1 of 1
[2025-09-06T16:50:59.233+0000] {taskinstance.py:2191} INFO - Executing <Task(EmailOperator): send_weather_email> on 2025-09-06 16:50:56.450281+00:00
[2025-09-06T16:50:59.235+0000] {standard_task_runner.py:60} INFO - Started process 268 to run task
[2025-09-06T16:50:59.238+0000] {standard_task_runner.py:87} INFO - Running: ['***', 'tasks', 'run', 'weather_etl_pipeline', 'send_weather_email', 'manual__2025-09-06T16:50:56.450281+00:00', '--job-id', '13', '--raw', '--subdir', 'DAGS_FOLDER/etlweather.py', '--cfg-path', '/tmp/tmpunzfovt5']
[2025-09-06T16:50:59.239+0000] {standard_task_runner.py:88} INFO - Job 13: Subtask send_weather_email
[2025-09-06T16:50:59.261+0000] {task_command.py:423} INFO - Running <TaskInstance: weather_etl_pipeline.send_weather_email manual__2025-09-06T16:50:56.450281+00:00 [running]> on host acffb6f403d4
[2025-09-06T16:50:59.296+0000] {taskinstance.py:2480} INFO - Exporting env vars: AIRFLOW_CTX_DAG_EMAIL='test@example.com' AIRFLOW_CTX_DAG_OWNER='***' AIRFLOW_CTX_DAG_ID='weather_etl_pipeline' AIRFLOW_CTX_TASK_ID='send_weather_email' AIRFLOW_CTX_EXECUTION_DATE='2025-09-06T16:50:56.450281+00:00' AIRFLOW_CTX_TRY_NUMBER='1' AIRFLOW_CTX_DAG_RUN_ID='manual__2025-09-06T16:50:56.450281+00:00'
[2025-09-06T16:50:59.303+0000] {logging_mixin.py:188} WARNING - /home/***/.local/lib/python3.8/site-packages/***/utils/email.py:154 RemovedInAirflow3Warning: Fetching SMTP credentials from configuration variables will be deprecated in a future release. Please set credentials using a connection instead.
[2025-09-06T16:50:59.304+0000] {email.py:270} INFO - Email alerting: attempt 1
[2025-09-06T16:51:01.019+0000] {taskinstance.py:2698} ERROR - Task failed with exception
Traceback (most recent call last):
  File "/home/airflow/.local/lib/python3.8/site-packages/airflow/models/taskinstance.py", line 433, in _execute_task
    result = execute_callable(context=context, **execute_callable_kwargs)
  File "/home/airflow/.local/lib/python3.8/site-packages/airflow/operators/email.py", line 79, in execute
    send_email(
  File "/home/airflow/.local/lib/python3.8/site-packages/airflow/utils/email.py", line 80, in send_email
    return backend(
  File "/home/airflow/.local/lib/python3.8/site-packages/airflow/utils/email.py", line 154, in send_email_smtp
    send_mime_email(e_from=mail_from, e_to=recipients, mime_msg=msg, conn_id=conn_id, dryrun=dryrun)
  File "/home/airflow/.local/lib/python3.8/site-packages/airflow/utils/email.py", line 280, in send_mime_email
    smtp_conn.login(smtp_user, smtp_password)
  File "/usr/local/lib/python3.8/smtplib.py", line 748, in login
    raise last_exception
  File "/usr/local/lib/python3.8/smtplib.py", line 737, in login
    (code, resp) = self.auth(
  File "/usr/local/lib/python3.8/smtplib.py", line 660, in auth
    raise SMTPAuthenticationError(code, resp)
smtplib.SMTPAuthenticationError: (535, b'5.7.8 Username and Password not accepted. For more information, go to\n5.7.8  https://support.google.com/mail/?p=BadCredentials 41be03b00d2f7-b4fa7484ec5sm9219592a12.49 - gsmtp')
[2025-09-06T16:51:01.036+0000] {taskinstance.py:1138} INFO - Marking task as FAILED. dag_id=weather_etl_pipeline, task_id=send_weather_email, execution_date=20250906T165056, start_date=20250906T165059, end_date=20250906T165101
[2025-09-06T16:51:01.046+0000] {email.py:270} INFO - Email alerting: attempt 1
[2025-09-06T16:51:02.516+0000] {email.py:270} INFO - Email alerting: attempt 1
[2025-09-06T16:51:04.012+0000] {taskinstance.py:826} ERROR - Failed to send email to: ['test@example.com']
Traceback (most recent call last):
  File "/home/airflow/.local/lib/python3.8/site-packages/airflow/models/taskinstance.py", line 2334, in _run_raw_task
    self._execute_task_with_callbacks(context, test_mode, session=session)
  File "/home/airflow/.local/lib/python3.8/site-packages/airflow/models/taskinstance.py", line 2499, in _execute_task_with_callbacks
    result = self._execute_task(context, task_orig)
  File "/home/airflow/.local/lib/python3.8/site-packages/airflow/models/taskinstance.py", line 2516, in _execute_task
    return _execute_task(self, context, task_orig)
  File "/home/airflow/.local/lib/python3.8/site-packages/airflow/models/taskinstance.py", line 433, in _execute_task
    result = execute_callable(context=context, **execute_callable_kwargs)
  File "/home/airflow/.local/lib/python3.8/site-packages/airflow/operators/email.py", line 79, in execute
    send_email(
  File "/home/airflow/.local/lib/python3.8/site-packages/airflow/utils/email.py", line 80, in send_email
    return backend(
  File "/home/airflow/.local/lib/python3.8/site-packages/airflow/utils/email.py", line 154, in send_email_smtp
    send_mime_email(e_from=mail_from, e_to=recipients, mime_msg=msg, conn_id=conn_id, dryrun=dryrun)
  File "/home/airflow/.local/lib/python3.8/site-packages/airflow/utils/email.py", line 280, in send_mime_email
    smtp_conn.login(smtp_user, smtp_password)
  File "/usr/local/lib/python3.8/smtplib.py", line 748, in login
    raise last_exception
  File "/usr/local/lib/python3.8/smtplib.py", line 737, in login
    (code, resp) = self.auth(
  File "/usr/local/lib/python3.8/smtplib.py", line 660, in auth
    raise SMTPAuthenticationError(code, resp)
smtplib.SMTPAuthenticationError: (535, b'5.7.8 Username and Password not accepted. For more information, go to\n5.7.8  https://support.google.com/mail/?p=BadCredentials 41be03b00d2f7-b4fa7484ec5sm9219592a12.49 - gsmtp')

During handling of the above exception, another exception occurred:

Traceback (most recent call last):
  File "/home/airflow/.local/lib/python3.8/site-packages/airflow/models/taskinstance.py", line 1000, in _email_alert
    send_email(task.email, subject, html_content)
  File "/home/airflow/.local/lib/python3.8/site-packages/airflow/utils/email.py", line 80, in send_email
    return backend(
  File "/home/airflow/.local/lib/python3.8/site-packages/airflow/utils/email.py", line 154, in send_email_smtp
    send_mime_email(e_from=mail_from, e_to=recipients, mime_msg=msg, conn_id=conn_id, dryrun=dryrun)
  File "/home/airflow/.local/lib/python3.8/site-packages/airflow/utils/email.py", line 280, in send_mime_email
    smtp_conn.login(smtp_user, smtp_password)
  File "/usr/local/lib/python3.8/smtplib.py", line 748, in login
    raise last_exception
  File "/usr/local/lib/python3.8/smtplib.py", line 737, in login
    (code, resp) = self.auth(
  File "/usr/local/lib/python3.8/smtplib.py", line 660, in auth
    raise SMTPAuthenticationError(code, resp)
smtplib.SMTPAuthenticationError: (535, b'5.7.8 Username and Password not accepted. For more information, go to\n5.7.8  https://support.google.com/mail/?p=BadCredentials d9443c01a7336-24903724b94sm237711385ad.35 - gsmtp')

During handling of the above exception, another exception occurred:

Traceback (most recent call last):
  File "/home/airflow/.local/lib/python3.8/site-packages/airflow/models/taskinstance.py", line 824, in _handle_failure
    task_instance.email_alert(error, failure_context["task"])
  File "/home/airflow/.local/lib/python3.8/site-packages/airflow/models/taskinstance.py", line 2946, in email_alert
    _email_alert(task_instance=self, exception=exception, task=task)
  File "/home/airflow/.local/lib/python3.8/site-packages/airflow/models/taskinstance.py", line 1002, in _email_alert
    send_email(task.email, subject, html_content_err)
  File "/home/airflow/.local/lib/python3.8/site-packages/airflow/utils/email.py", line 80, in send_email
    return backend(
  File "/home/airflow/.local/lib/python3.8/site-packages/airflow/utils/email.py", line 154, in send_email_smtp
    send_mime_email(e_from=mail_from, e_to=recipients, mime_msg=msg, conn_id=conn_id, dryrun=dryrun)
  File "/home/airflow/.local/lib/python3.8/site-packages/airflow/utils/email.py", line 280, in send_mime_email
    smtp_conn.login(smtp_user, smtp_password)
  File "/usr/local/lib/python3.8/smtplib.py", line 748, in login
    raise last_exception
  File "/usr/local/lib/python3.8/smtplib.py", line 737, in login
    (code, resp) = self.auth(
  File "/usr/local/lib/python3.8/smtplib.py", line 660, in auth
    raise SMTPAuthenticationError(code, resp)
smtplib.SMTPAuthenticationError: (535, b'5.7.8 Username and Password not accepted. For more information, go to\n5.7.8  https://support.google.com/mail/?p=BadCredentials d2e1a72fcca58-7723f095d3esm21692174b3a.97 - gsmtp')
[2025-09-06T16:51:04.034+0000] {standard_task_runner.py:107} ERROR - Failed to execute job 13 for task send_weather_email ((535, b'5.7.8 Username and Password not accepted. For more information, go to\n5.7.8  https://support.google.com/mail/?p=BadCredentials 41be03b00d2f7-b4fa7484ec5sm9219592a12.49 - gsmtp'); 268)
[2025-09-06T16:51:04.051+0000] {local_task_job_runner.py:234} INFO - Task exited with return code 1
[2025-09-06T16:51:04.065+0000] {taskinstance.py:3280} INFO - 0 downstream tasks scheduled from follow-on schedule check
